<?xml version="1.0" ?>
<!-- 
 ...........       ____  _ __
 |  ,-^-,  |      / __ )(_) /_______________ _____  ___
 | (  O  ) |     / __  / / __/ ___/ ___/ __ `/_  / / _ \
 | / ,..´  |    / /_/ / / /_/ /__/ /  / /_/ / / /_/  __/
    +.......   /_____/_/\__/\___/_/   \__,_/ /___/\___/
 
MIT License

Copyright (c) 2022 Bitcraze
-->

<sdf version="1.6">
  <world name="crazyflie_world">
    <physics name="1ms" type="ignored">
      <max_step_size>0.001</max_step_size>
      <real_time_factor>1.0</real_time_factor>
    </physics>
    <plugin
      filename="gz-sim-physics-system"
      name="gz::sim::systems::Physics">
    </plugin>
    <plugin
      filename="gz-sim-user-commands-system"
      name="gz::sim::systems::UserCommands">
    </plugin>
    <plugin
      filename="gz-sim-scene-broadcaster-system"
      name="gz::sim::systems::SceneBroadcaster">
    </plugin>
    <plugin
      filename="gz-sim-sensors-system"
      name="gz::sim::systems::Sensors">
      <render_engine>ogre2</render_engine>
    </plugin>

    <light type="directional" name="sun">
      <cast_shadows>true</cast_shadows>
      <pose>0 0 10 0 0 0</pose>
      <diffuse>0.8 0.8 0.8 1</diffuse>
      <specular>0.2 0.2 0.2 1</specular>
      <attenuation>
        <range>1000</range>
        <constant>0.9</constant>
        <linear>0.01</linear>
        <quadratic>0.001</quadratic>
      </attenuation>
      <direction>-0.5 0.1 -0.9</direction>
    </light>

    <model name="ground_plane">
      <static>true</static>
      <link name="link">
        <collision name="collision">
          <geometry>
            <plane>
              <normal>0 0 1</normal>
              <size>100 100</size>
            </plane>
          </geometry>
        </collision>
        <visual name="visual">
          <geometry>
            <plane>
              <normal>0 0 1</normal>
              <size>100 100</size>
            </plane>
          </geometry>
          <material>
            <ambient>0.8 0.8 0.8 1</ambient>
            <diffuse>0.8 0.8 0.8 1</diffuse>
            <specular>0.8 0.8 0.8 1</specular>
          </material>
        </visual>
      </link>
    </model>
    <include>
      <uri>model://crazyflie</uri>
      <name>crazyflie_01</name>
      <pose>-1.2 0 0 0 0 0</pose>
    </include>

    <include>
      <uri>model://load</uri>
      <name>the_load</name>
      <pose>0 0 0 0 0 0</pose>
    </include>

    <include>
      <uri>model://segment</uri>
      <name>segment_01</name>
      <pose>-0.95 0 0 0 0 0</pose> 
    </include>

    <joint name="drone_to_cable_01" type="revolute">
      <pose relative_to='crazyflie_01::hook_link'>0 0 0 0 0 0</pose> 
      <parent>crazyflie_01::hook_link</parent> 
      <child>segment_01::segment_link</child>
      <axis><xyz>0 1 0</xyz></axis>
    </joint>

    <include>
      <uri>model://segment</uri>
      <name>segment_10</name>
      <pose>-0.45 0 0 0 0 0</pose>
    </include>

    <joint name="segment_09_to_10" type="revolute">
      <pose relative_to='segment_01::segment_end'>0 0 0 0 0 0</pose>
      <parent>segment_01::segment_end</parent>
      <child>segment_10::segment_link</child>
      <axis><xyz>0 1 0</xyz></axis>
    </joint>

    <joint name="cable_10_to_load" type="revolute">
      <pose relative_to='segment_10::segment_end'>0 0 0 0 0 0</pose>
      <parent>segment_10::segment_end</parent>
      <child>the_load::top_center_hook</child>
      <axis><xyz>0 1 0</xyz></axis>
    </joint>

    <plugin
      filename="gz-sim-odometry-publisher-system"
      name="gz::sim::systems::OdometryPublisher">
      <dimensions>3</dimensions>
    </plugin>
  </world>
</sdf>
